<?xml version="1.0" ?>
<robot name="aigo">
 
    <link name="base_link">
        <visual>
            <origin xyz=" 0 0 0" rpy="0 0 0" />
            <geometry>
                <cylinder length="0.24" radius="0.12"/>
            </geometry>
            <material name="yellow">
                <color rgba="1 0.4 0 1"/>
            </material>
        </visual>
    </link>
 
    <joint name="left_wheel_joint" type="continuous">
        <origin xyz="-0.11 0.105 -0.05" rpy="0 0 0"/>
        <parent link="base_link"/>
        <child link="left_wheel_link"/>
        <axis xyz="0 1 0"/>
    </joint>
 
    <link name="left_wheel_link">
        <visual>
            <origin xyz="0 0 0" rpy="1.5707 0 0" />
            <geometry>
                <cylinder radius="0.0425" length = "0.05"/>
            </geometry>
            <material name="white">
                <color rgba="1 1 1 0.9"/>
            </material>
        </visual>
    </link>
 
    <joint name="right_wheel_joint" type="continuous">
        <origin xyz="-0.11 -0.105 -0.05" rpy="0 0 0"/>
        <parent link="base_link"/>
        <child link="right_wheel_link"/>
        <axis xyz="0 1 0"/>
    </joint>
 
    <link name="right_wheel_link">
        <visual>
            <origin xyz="0 0 0" rpy="1.5707 0 0" />
            <geometry>
                <cylinder radius="0.0425" length = "0.05"/>
            </geometry>
            <material name="white">
                <color rgba="1 1 1 0.9"/>
            </material>
        </visual>
    </link>
 
    <joint name="left_front_joint" type="continuous">
        <origin xyz="0.11 0.105 -0.05" rpy="0 0 0"/>
        <parent link="base_link"/>
        <child link="left_front_link"/>
        <axis xyz="0 1 0"/>
    </joint>
 
    <link name="left_front_link">
        <visual>
            <origin xyz="0 0 0" rpy="1.5707 0 0" />
            <geometry>
                <cylinder radius="0.0425" length = "0.05"/>
            </geometry>
            <material name="white">
                <color rgba="1 1 1 0.9"/>
            </material>
        </visual>
    </link>
 
    <joint name="right_front_joint" type="continuous">
        <origin xyz="0.11 -0.105 -0.05" rpy="0 0 0"/>
        <parent link="base_link"/>
        <child link="right_front_link"/>
        <axis xyz="0 1 0"/>
    </joint>
 
    <link name="right_front_link">
        <visual>
            <origin xyz="0 0 0" rpy="1.5707 0 0" />
            <geometry>
                <cylinder radius="0.0425" length = "0.05"/>
            </geometry>
            <material name="white">
                <color rgba="1 1 1 0.9"/>
            </material>
        </visual>
    </link>

 
    <link name="laser_link">
		<visual>
			<origin xyz=" 0 0 0 " rpy="0 0 0" />
			<geometry>
				<cylinder length="0.05" radius="0.05"/>
			</geometry>
			<material name="black"/>
		</visual>
    </link>
 
    <joint name="laser_joint" type="fixed">
        <origin xyz="0.11 0 0.105" rpy="0 0 0"/>
        <parent link="base_link"/>
        <child link="laser_link"/>
    </joint>
    <link name="gps"/>
        <joint name="gps_to_base_link" type="fixed">
            <parent link="base_link"/>
            <child link="gps"/>
            <origin xyz="0 0 0" rpy="0 0 0"/>
        </joint>
    <link name="imu_link"/>
        <joint name="imu_to_base_link" type="fixed">
            <parent link="base_link"/>
            <child link="imu_link"/>
            <origin xyz="0 0 0" rpy="0 0 0"/>
        </joint>

</robot>
